<?xml version="1.0"?>
<!-- Author: James Avtges
     Email: jamesavtges2022@u.northwestern.edu
     Date: 10/26/2022   -->
<robot name="hsa_robot" xmlns:xacro="http://ros.org/wiki/xacro">

    <material name="gray">
	    <color rgba="0.5 0.5 0.5 1.0"/>
	</material>

    <material name="red">
        <color rgba="0.8 0.0 0.0 1.0"/>
    </material>

    <material name="blue">
        <color rgba="0.0 0.0 0.8 1.0"/>
    </material>
	
	<xacro:property name="torso_width" value="0.14" />
    <xacro:property name="torso_height" value="0.16" />
    <xacro:property name="torso_depth" value="0.02" />
    <xacro:property name="torso_mass" value="0.01" />

	<xacro:property name="leg_length" value="0.4" />
	<xacro:property name="leg_radius" value="0.025"/>
	<xacro:property name="leg_mass" value="0.04" />
	
	<xacro:property name="foot_width" value="0.1" />
    <xacro:property name="foot_height" value="0.1" />
    <xacro:property name="foot_depth" value="0.01" />
	<xacro:property name="foot_mass" value="0.01" />

    <xacro:property name="leg_fl_x" value="0.035" />
    <xacro:property name="leg_fl_y" value="0.06" />

    <xacro:property name="leg_fr_x" value="0.035" />
    <xacro:property name="leg_fr_y" value="-0.06" />

    <xacro:property name="leg_rl_x" value="-0.035" />
    <xacro:property name="leg_rl_y" value="0.06" />

    <xacro:property name="leg_rr_x" value="-0.035" />
    <xacro:property name="leg_rr_y" value="-0.06" />

    <xacro:property name="foot_fl_x" value="0.4" />
    <xacro:property name="foot_fl_y" value="0.4" />

    <xacro:property name="foot_fr_x" value="0.4" />
    <xacro:property name="foot_fr_y" value="0.4" />

    <xacro:property name="foot_rl_x" value="0.4" />
    <xacro:property name="foot_rl_y" value="0.4" />

    <xacro:property name="foot_rr_x" value="0.4" />
    <xacro:property name="foot_rr_y" value="0.4" />


    <link name="dummy">

        <inertial>
      			<origin rpy="0 0 0" xyz="0.0 0.0 0.0"/>
			<mass value = "0.001"/>
			
			<!-- Fix the inertia tag-->
			<inertia ixx="0" 
                     iyy="0" 
                     izz="0"
                     ixy="0"
                     ixz="0"
                     iyz="0"/>
    	</inertial>
    </link>
		
	<link name="base_link">
		<visual>
			<geometry>
				<box size="${torso_width} ${torso_height} ${torso_depth}" />
			</geometry>
            <material name="gray"/>
			
			<origin rpy="0 0 0" xyz="0.0 0.0 0.0"/>
		</visual>
	
		<inertial>
      			<origin rpy="0 0 0" xyz="0.0 0.0 0.0"/>
			<mass value = "${torso_mass}"/>
			
			<!-- Fix the inertia tag-->
			<inertia ixx="${(1.0/12.0) * torso_mass * ( (torso_height * torso_height) + (torso_depth * torso_depth) ) }" 
                                 iyy="${(1.0/12.0) * torso_mass * ( (torso_width * torso_width) + (torso_depth * torso_depth) ) }" 
                                 izz="${(1.0/12.0) * torso_mass * ( (torso_width * torso_width) + (torso_height * torso_height) ) }"
                                 ixy="0"
                                 ixz="0"
                                 iyz="0"/>
    	</inertial>

		<collision>
      			<origin rpy="0 0 0" xyz="0.0 0.0 0.0"/>
    	  		<geometry>
        			<box size="${torso_width} ${torso_height} ${torso_depth}" />
     			</geometry>
		</collision>        		
    </link>

    <joint name="dummy_joint" type="fixed">
        <parent link="dummy"/>
        <child link="base_link"/>
    </joint>

    <xacro:macro name="leg" params="leg_x leg_y name">
        <link name="${name}">
            <visual>
                <geometry>
                    <box size="0.035 0.035 0.05" />
                </geometry>
                <material name="blue"/>
                <origin rpy="0 0 0" xyz="0 0 -0.025"/>
                <!-- <origin rpy="0 0 0" xyz="${leg_x} ${leg_y} -0.025"/> -->
            </visual>

            <inertial>
                <origin rpy="0 0 0" xyz="${leg_x} ${leg_y} -0.025"/>
                <mass value = "0.02"/>

                <inertia ixx="${(1.0/12.0) * 0.02 * ( (0.035 * 0.035) + (0.05 * 0.05) ) }" 
                                 iyy="${(1.0/12.0) * 0.02 * ( (0.035 * 0.035) + (0.05 * 0.05) ) }" 
                                 izz="${(1.0/12.0) * 0.02 * ( (0.035 * 0.035) + (0.035 * 0.035) ) }"
                                 ixy="0"
                                 ixz="0"
                                 iyz="0"/>

            </inertial>

            <collision>
                <origin rpy="0 0 0" xyz="${leg_x} ${leg_y} -0.025"/>
                <geometry>
                    <box size="0.035 0.035 0.05" />
                </geometry>

            </collision>
        </link>
    </xacro:macro>


    <xacro:macro name="foot" params="leg_x leg_y name">
        <link name="${name}">
            <visual>
                <geometry>
                    <box size="0.035 0.035 0.02" />
                </geometry>
                <material name="red"/>
                <origin rpy="0 0 0" xyz="0 0 0"/>
                <!-- <origin rpy="0 0 0" xyz="${leg_x} ${leg_y} -0.06"/> -->

            </visual>

            <inertial>
                <origin rpy="0 0 0" xyz="${leg_x} ${leg_y} -0.06"/>
                <mass value = "${foot_mass}"/>

                <inertia ixx="${(1.0/12.0) * foot_mass * ( (0.035 * 0.035) + (0.01 * 0.01) ) }" 
                                 iyy="${(1.0/12.0) * foot_mass * ( (0.035 * 0.035) + (0.01 * 0.01) ) }" 
                                 izz="${(1.0/12.0) * foot_mass * ( (0.035 * 0.035) + (0.035 * 0.035) ) }"
                                 ixy="0"
                                 ixz="0"
                                 iyz="0"/>

            </inertial>

            <collision>
                <origin rpy="0 0 0" xyz="${leg_x} ${leg_y} -0.06"/>
                <geometry>
                    <box size="0.035 0.035 0.02" />
                </geometry>

            </collision>
        </link>
    </xacro:macro>

    <xacro:macro name="leg_joint" params="link_child name x y">

        <joint name="${name}" type="revolute">
            <!-- <origin xyz="${x} ${y} 0.0" rpy="0 0 0" /> -->
            <origin xyz="${x} ${y} -0.01" rpy="0 0 0" />
            <axis xyz = "0 1 0" />
            <parent link="base_link" />
            <child link="${link_child}" />
                    <!-- What to set these to? -->
            <limit velocity="1.0" effort="10" lower="-0.25" upper="0.25"/>
        </joint>

    </xacro:macro>

    <xacro:macro name="foot_joint" params="link_parent link_child name x y">

        <joint name="${name}" type="prismatic">
            <origin xyz="0.0 0.0 -0.06" rpy="0 0 0" />
            <axis xyz = "0 0 1" />
            <parent link="${link_parent}" />
            <child link="${link_child}" />
                    <!-- What to set these to? -->
            <limit velocity="1.0" effort="10" lower="-0.008" upper="0.001"/>
        </joint>

    </xacro:macro>


    <!-- Xacro macros for our legs -->
    <xacro:leg leg_x="${leg_fl_x}" leg_y="${leg_fl_y}" name="leg_fl">
    </xacro:leg>

    <xacro:leg leg_x="${leg_fr_x}" leg_y="${leg_fr_y}" name="leg_fr">
    </xacro:leg>

    <xacro:leg leg_x="${leg_rl_x}" leg_y="${leg_rl_y}" name="leg_rl">
    </xacro:leg>

    <xacro:leg leg_x="${leg_rr_x}" leg_y="${leg_rr_y}" name="leg_rr">
    </xacro:leg>


    <!-- Xacro macros for our feet -->
    <xacro:foot leg_x="${leg_fl_x}" leg_y="${leg_fl_y}" name="foot_fl">
    </xacro:foot>

    <xacro:foot leg_x="${leg_fr_x}" leg_y="${leg_fr_y}" name="foot_fr">
    </xacro:foot>

    <xacro:foot leg_x="${leg_rl_x}" leg_y="${leg_rl_y}" name="foot_rl">
    </xacro:foot>

    <xacro:foot leg_x="${leg_rr_x}" leg_y="${leg_rr_y}" name="foot_rr">
    </xacro:foot>

    <!-- Xacro macros for the links between our base link (the body) and the leg -->
    <xacro:leg_joint link_child="leg_fl" name="base_to_leg_fl" x="${leg_fl_x}" y="${leg_fl_y}">
    </xacro:leg_joint>

    <xacro:leg_joint link_child="leg_fr" name="base_to_leg_fr" x="${leg_fr_x}" y="${leg_fr_y}">
    </xacro:leg_joint>

    <xacro:leg_joint link_child="leg_rl" name="base_to_leg_rl" x="${leg_rl_x}" y="${leg_rl_y}">
    </xacro:leg_joint>

    <xacro:leg_joint link_child="leg_rr" name="base_to_leg_rr" x="${leg_rr_x}" y="${leg_rr_y}">
    </xacro:leg_joint>


    <!-- Xacro macros for the links between our legs and our feet -->
    <xacro:foot_joint link_parent="leg_fl" link_child="foot_fl" name="leg_to_foot_fl" x="${leg_fl_x}" y="${leg_fl_y}">
    </xacro:foot_joint>

    <xacro:foot_joint link_parent="leg_fr" link_child="foot_fr" name="leg_to_foot_fr" x="${leg_fr_x}" y="${leg_fr_y}">
    </xacro:foot_joint>

    <xacro:foot_joint link_parent="leg_rl" link_child="foot_rl" name="leg_to_foot_rl" x="${leg_rl_x}" y="${leg_rl_y}">
    </xacro:foot_joint>

    <xacro:foot_joint link_parent="leg_rr" link_child="foot_rr" name="leg_to_foot_rr" x="${leg_rr_x}" y="${leg_rr_y}">
    </xacro:foot_joint>


	
	
</robot>